[2024-01-18T03:03:46.700+0000] {taskinstance.py:1083} INFO - Dependencies all met for <TaskInstance: pythonoperator.t1 manual__2024-01-18T03:03:44.245593+00:00 [queued]>
[2024-01-18T03:03:46.707+0000] {taskinstance.py:1083} INFO - Dependencies all met for <TaskInstance: pythonoperator.t1 manual__2024-01-18T03:03:44.245593+00:00 [queued]>
[2024-01-18T03:03:46.708+0000] {taskinstance.py:1279} INFO - 
--------------------------------------------------------------------------------
[2024-01-18T03:03:46.708+0000] {taskinstance.py:1280} INFO - Starting attempt 1 of 1
[2024-01-18T03:03:46.708+0000] {taskinstance.py:1281} INFO - 
--------------------------------------------------------------------------------
[2024-01-18T03:03:46.717+0000] {taskinstance.py:1300} INFO - Executing <Task(PythonOperator): t1> on 2024-01-18 03:03:44.245593+00:00
[2024-01-18T03:03:46.724+0000] {standard_task_runner.py:55} INFO - Started process 1799 to run task
[2024-01-18T03:03:46.727+0000] {standard_task_runner.py:82} INFO - Running: ['***', 'tasks', 'run', 'pythonoperator', 't1', 'manual__2024-01-18T03:03:44.245593+00:00', '--job-id', '111', '--raw', '--subdir', 'DAGS_FOLDER/19-pythonoperator.py', '--cfg-path', '/tmp/tmpt5kx8eep']
[2024-01-18T03:03:46.728+0000] {standard_task_runner.py:83} INFO - Job 111: Subtask t1
[2024-01-18T03:03:46.758+0000] {task_command.py:388} INFO - Running <TaskInstance: pythonoperator.t1 manual__2024-01-18T03:03:44.245593+00:00 [running]> on host cb9489d15b76
[2024-01-18T03:03:46.797+0000] {taskinstance.py:1509} INFO - Exporting the following env vars:
AIRFLOW_CTX_DAG_OWNER=***
AIRFLOW_CTX_DAG_ID=pythonoperator
AIRFLOW_CTX_TASK_ID=t1
AIRFLOW_CTX_EXECUTION_DATE=2024-01-18T03:03:44.245593+00:00
AIRFLOW_CTX_TRY_NUMBER=1
AIRFLOW_CTX_DAG_RUN_ID=manual__2024-01-18T03:03:44.245593+00:00
[2024-01-18T03:03:46.817+0000] {taskinstance.py:1768} ERROR - Task failed with exception
Traceback (most recent call last):
  File "/home/airflow/.local/lib/python3.7/site-packages/airflow/operators/python.py", line 175, in execute
    return_value = self.execute_callable()
  File "/home/airflow/.local/lib/python3.7/site-packages/airflow/operators/python.py", line 192, in execute_callable
    return self.python_callable(*self.op_args, **self.op_kwargs)
  File "/opt/airflow/dags/19-pythonoperator.py", line 22, in data_cleaner
    dataset.loc[(dataset['Idade'] < 0 | dataset['Idade'] > 120), 'Idade'] = mediana
  File "/home/airflow/.local/lib/python3.7/site-packages/pandas/core/generic.py", line 1538, in __nonzero__
    f"The truth value of a {type(self).__name__} is ambiguous. "
ValueError: The truth value of a Series is ambiguous. Use a.empty, a.bool(), a.item(), a.any() or a.all().
[2024-01-18T03:03:46.829+0000] {taskinstance.py:1323} INFO - Marking task as FAILED. dag_id=pythonoperator, task_id=t1, execution_date=20240118T030344, start_date=20240118T030346, end_date=20240118T030346
[2024-01-18T03:03:46.843+0000] {standard_task_runner.py:105} ERROR - Failed to execute job 111 for task t1 (The truth value of a Series is ambiguous. Use a.empty, a.bool(), a.item(), a.any() or a.all().; 1799)
[2024-01-18T03:03:46.861+0000] {local_task_job.py:208} INFO - Task exited with return code 1
[2024-01-18T03:03:46.872+0000] {taskinstance.py:2578} INFO - 0 downstream tasks scheduled from follow-on schedule check
