[2024-01-20T02:53:25.627+0000] {taskinstance.py:1083} INFO - Dependencies all met for <TaskInstance: hook.select_data_task manual__2024-01-20T02:53:21.097503+00:00 [queued]>
[2024-01-20T02:53:25.643+0000] {taskinstance.py:1083} INFO - Dependencies all met for <TaskInstance: hook.select_data_task manual__2024-01-20T02:53:21.097503+00:00 [queued]>
[2024-01-20T02:53:25.644+0000] {taskinstance.py:1279} INFO - 
--------------------------------------------------------------------------------
[2024-01-20T02:53:25.645+0000] {taskinstance.py:1280} INFO - Starting attempt 1 of 1
[2024-01-20T02:53:25.645+0000] {taskinstance.py:1281} INFO - 
--------------------------------------------------------------------------------
[2024-01-20T02:53:25.657+0000] {taskinstance.py:1300} INFO - Executing <Task(PythonOperator): select_data_task> on 2024-01-20 02:53:21.097503+00:00
[2024-01-20T02:53:25.663+0000] {standard_task_runner.py:55} INFO - Started process 52316 to run task
[2024-01-20T02:53:25.666+0000] {standard_task_runner.py:82} INFO - Running: ['***', 'tasks', 'run', 'hook', 'select_data_task', 'manual__2024-01-20T02:53:21.097503+00:00', '--job-id', '139', '--raw', '--subdir', 'DAGS_FOLDER/24-hooks.py', '--cfg-path', '/tmp/tmpjv4z_gty']
[2024-01-20T02:53:25.667+0000] {standard_task_runner.py:83} INFO - Job 139: Subtask select_data_task
[2024-01-20T02:53:25.720+0000] {task_command.py:388} INFO - Running <TaskInstance: hook.select_data_task manual__2024-01-20T02:53:21.097503+00:00 [running]> on host cb9489d15b76
[2024-01-20T02:53:25.764+0000] {taskinstance.py:1509} INFO - Exporting the following env vars:
AIRFLOW_CTX_DAG_OWNER=***
AIRFLOW_CTX_DAG_ID=hook
AIRFLOW_CTX_TASK_ID=select_data_task
AIRFLOW_CTX_EXECUTION_DATE=2024-01-20T02:53:21.097503+00:00
AIRFLOW_CTX_TRY_NUMBER=1
AIRFLOW_CTX_DAG_RUN_ID=manual__2024-01-20T02:53:21.097503+00:00
[2024-01-20T02:53:25.765+0000] {taskinstance.py:1768} ERROR - Task failed with exception
Traceback (most recent call last):
  File "/home/airflow/.local/lib/python3.7/site-packages/airflow/operators/python.py", line 175, in execute
    return_value = self.execute_callable()
  File "/home/airflow/.local/lib/python3.7/site-packages/airflow/operators/python.py", line 192, in execute_callable
    return self.python_callable(*self.op_args, **self.op_kwargs)
  File "/opt/airflow/dags/24-hooks.py", line 21, in select_data
    records = pg_hook.get_records('select * from teste2;', autocommit=True)
TypeError: get_records() got an unexpected keyword argument 'autocommit'
[2024-01-20T02:53:25.773+0000] {taskinstance.py:1323} INFO - Marking task as FAILED. dag_id=hook, task_id=select_data_task, execution_date=20240120T025321, start_date=20240120T025325, end_date=20240120T025325
[2024-01-20T02:53:25.780+0000] {standard_task_runner.py:105} ERROR - Failed to execute job 139 for task select_data_task (get_records() got an unexpected keyword argument 'autocommit'; 52316)
[2024-01-20T02:53:25.800+0000] {local_task_job.py:208} INFO - Task exited with return code 1
[2024-01-20T02:53:26.218+0000] {taskinstance.py:2578} INFO - 0 downstream tasks scheduled from follow-on schedule check
